Workbook

Sheet KPI Dashboard Data
A1: Al-Noor Trading — KPI Dashboard Data (June 2026)
A2: KPI Metric | B2: Value | C2: Unit | D2: Formula / Logic | E2: Category
A3: Total Revenue | B3: ='Financial Summary'!B6 | C3: PKR | D3: SUM(Daily Qty × Sale Price) for all 161 products × 30 days | E3: Revenue
A4: Total COGS | B4: ='Financial Summary'!B7 | C4: PKR | D4: SUM(Daily Qty × Cost Price) for all 161 products × 30 days | E4: Revenue
A5: Gross Profit | B5: ='Financial Summary'!B8 | C5: PKR | D5: Total Revenue − Total COGS | E5: Profitability
A6: Gross Profit Margin % | B6: ='Financial Summary'!B9 | C6: % | D6: Gross Profit ÷ Revenue × 100 | E6: Profitability
A7: Total Operating Expenses | B7: ='Financial Summary'!B10 | C7: PKR | D7: SUPPLIES only — 12 active records; 1 voided excluded; total = PKR 31,589.99 | E7: Expenses
A8: Net Profit | B8: ='Financial Summary'!B11 | C8: PKR | D8: Gross Profit − Total Operating Expenses | E8: Profitability
A9: Net Profit Margin % | B9: ='Financial Summary'!B12 | C9: % | D9: Net Profit ÷ Revenue × 100 | E9: Profitability
A10: Total Cash Inflows | B10: ='Financial Summary'!B16 | C10: PKR | D10: Sum of all 30 daily sales receipts | E10: Cash Flow
A11: Total Cash Outflows | B11: ='Financial Summary'!B17 | C11: PKR | D11: Total COGS outflow + Operating expense outflow | E11: Cash Flow
A12: Net Cash Flow | B12: ='Financial Summary'!B18 | C12: PKR | D12: Cash Inflows − Cash Outflows | E12: Cash Flow
A13: Closing Inventory Value | B13: ='Financial Summary'!B22 | C13: PKR | D13: Qty in Hand × Cost Price for all products | E13: Inventory
A14: Total Active SKUs | B14: ='Financial Summary'!B23 | C14: Count | D14: Count of product records in Sales Data sheet | E14: Inventory
A15: Low / Out-of-Stock Items | B15: ='Financial Summary'!B24 | C15: Count | D15: Products where Stock Status = "Low Stock" | E15: Inventory
A16: Avg Daily Sales Volume | B16: ='Financial Summary'!B25 | C16: Units/day | D16: Total units sold ÷ 30 days | E16: Inventory
A17: Active Expense Records | B17: =12 | C17: Count | D17: 12 ACTIVE; SUPPLIES category; vendors: Falak Foods, Gul Ahmed, GSK Pakistan, Bazm-e-iqbal | E17: Expenses
A18: Voided Expense Records | B18: =1 | C18: Count | D18: Voided: 2026-05-14 | Grey | PKR 1,500.00 | Excluded from all totals | E18: Expenses
A19: Source: Sales Data sheet (161 SKUs, 30 days June 2026). Expenses: SUPPLIES only, PKR 31,589.99 (12 active). All vendors Pakistani (Falak Foods, Gul Ahmed, GSK Pakistan, Bazm-e-iqbal, Grey). Tax = PKR 0.00 on all records.
A20: Source: Sales Data sheet (161 SKUs, 30 days May 2026). Expenses: SUPPLIES only, PKR 31,589.99 (12 active). All vendors Pakistani (Falak Foods, Gul Ahmed, GSK Pakistan, Bazm-e-iqbal, Grey). Tax = PKR 0.00 on all records.

Sheet Cash Flow Statement
A1: Al-Noor Trading — Cash Flow Statement (June 2026)
A2: Date | B2: Day | C2: Type | D2: Description | E2: Reference | F2: Amount (PKR)
A3: 2026-06-01 | B3: Mon | C3: INFLOW | D3: Daily Sales Revenue | E3: REV-06-01 | F3: =SUMPRODUCT('Sales Data'!O3:O163,'Sales Data'!$L$3:$L$163)
A4: 2026-06-01 | B4: Mon | C4: OUTFLOW | D4: Daily COGS — Inventory Cost | E4: COGS-06-01 | F4: =SUMPRODUCT('Sales Data'!O3:O163,'Sales Data'!$K$3:$K$163)
A5: 2026-06-01 | B5: Mon | C5: OUTFLOW | D5: Operating Expense: Office stationery & supplies | E5: EXP-06-01 | F5: 2500
A6: 2026-06-02 | B6: Tue | C6: INFLOW | D6: Daily Sales Revenue | E6: REV-06-02 | F6: =SUMPRODUCT('Sales Data'!P3:P163,'Sales Data'!$L$3:$L$163)
A7: 2026-06-02 | B7: Tue | C7: OUTFLOW | D7: Daily COGS — Inventory Cost | E7: COGS-06-02 | F7: =SUMPRODUCT('Sales Data'!P3:P163,'Sales Data'!$K$3:$K$163)
A8: 2026-06-02 | B8: Tue | C8: OUTFLOW | D8: Operating Expense: Packaging materials | E8: EXP-06-02 | F8: 3200
A9: 2026-06-03 | B9: Wed | C9: INFLOW | D9: Daily Sales Revenue | E9: REV-06-03 | F9: =SUMPRODUCT('Sales Data'!Q3:Q163,'Sales Data'!$L$3:$L$163)
A10: 2026-06-03 | B10: Wed | C10: OUTFLOW | D10: Daily COGS — Inventory Cost | E10: COGS-06-03 | F10: =SUMPRODUCT('Sales Data'!Q3:Q163,'Sales Data'!$K$3:$K$163)
A11: 2026-06-04 | B11: Thu | C11: INFLOW | D11: Daily Sales Revenue | E11: REV-06-04 | F11: =SUMPRODUCT('Sales Data'!R3:R163,'Sales Data'!$L$3:$L$163)
A12: 2026-06-04 | B12: Thu | C12: OUTFLOW | D12: Daily COGS — Inventory Cost | E12: COGS-06-04 | F12: =SUMPRODUCT('Sales Data'!R3:R163,'Sales Data'!$K$3:$K$163)
A13: 2026-06-04 | B13: Thu | C13: OUTFLOW | D13: Operating Expense: Cleaning & hygiene supplies | E13: EXP-06-04 | F13: 1800
A14: 2026-06-05 | B14: Fri | C14: INFLOW | D14: Daily Sales Revenue | E14: REV-06-05 | F14: =SUMPRODUCT('Sales Data'!S3:S163,'Sales Data'!$L$3:$L$163)
A15: 2026-06-05 | B15: Fri | C15: OUTFLOW | D15: Daily COGS — Inventory Cost | E15: COGS-06-05 | F15: =SUMPRODUCT('Sales Data'!S3:S163,'Sales Data'!$K$3:$K$163)
A16: 2026-06-06 | B16: Sat | C16: INFLOW | D16: Daily Sales Revenue | E16: REV-06-06 | F16: =SUMPRODUCT('Sales Data'!T3:T163,'Sales Data'!$L$3:$L$163)
A17: 2026-06-06 | B17: Sat | C17: OUTFLOW | D17: Daily COGS — Inventory Cost | E17: COGS-06-06 | F17: =SUMPRODUCT('Sales Data'!T3:T163,'Sales Data'!$K$3:$K$163)
A18: 2026-06-06 | B18: Sat | C18: OUTFLOW | D18: Operating Expense: Display & shelving items | E18: EXP-06-06 | F18: 4500
A19: 2026-06-07 | B19: Sun | C19: INFLOW | D19: Daily Sales Revenue | E19: REV-06-07 | F19: =SUMPRODUCT('Sales Data'!U3:U163,'Sales Data'!$L$3:$L$163)
A20: 2026-06-07 | B20: Sun | C20: OUTFLOW | D20: Daily COGS — Inventory Cost | E20: COGS-06-07 | F20: =SUMPRODUCT('Sales Data'!U3:U163,'Sales Data'!$K$3:$K$163)
A21: 2026-06-08 | B21: Mon | C21: INFLOW | D21: Daily Sales Revenue | E21: REV-06-08 | F21: =SUMPRODUCT('Sales Data'!V3:V163,'Sales Data'!$L$3:$L$163)
A22: 2026-06-08 | B22: Mon | C22: OUTFLOW | D22: Daily COGS — Inventory Cost | E22: COGS-06-08 | F22: =SUMPRODUCT('Sales Data'!V3:V163,'Sales Data'!$K$3:$K$163)
A23: 2026-06-08 | B23: Mon | C23: OUTFLOW | D23: Operating Expense: Printer paper & ink cartridges | E23: EXP-06-08 | F23: 2750
A24: 2026-06-09 | B24: Tue | C24: INFLOW | D24: Daily Sales Revenue | E24: REV-06-09 | F24: =SUMPRODUCT('Sales Data'!W3:W163,'Sales Data'!$L$3:$L$163)
A25: 2026-06-09 | B25: Tue | C25: OUTFLOW | D25: Daily COGS — Inventory Cost | E25: COGS-06-09 | F25: =SUMPRODUCT('Sales Data'!W3:W163,'Sales Data'!$K$3:$K$163)
A26: 2026-06-10 | B26: Wed | C26: INFLOW | D26: Daily Sales Revenue | E26: REV-06-10 | F26: =SUMPRODUCT('Sales Data'!X3:X163,'Sales Data'!$L$3:$L$163)
A27: 2026-06-10 | B27: Wed | C27: OUTFLOW | D27: Daily COGS — Inventory Cost | E27: COGS-06-10 | F27: =SUMPRODUCT('Sales Data'!X3:X163,'Sales Data'!$K$3:$K$163)
A28: 2026-06-10 | B28: Wed | C28: OUTFLOW | D28: Operating Expense: Storage boxes & labels | E28: EXP-06-10 | F28: 1950
A29: 2026-06-11 | B29: Thu | C29: INFLOW | D29: Daily Sales Revenue | E29: REV-06-11 | F29: =SUMPRODUCT('Sales Data'!Y3:Y163,'Sales Data'!$L$3:$L$163)
A30: 2026-06-11 | B30: Thu | C30: OUTFLOW | D30: Daily COGS — Inventory Cost | E30: COGS-06-11 | F30: =SUMPRODUCT('Sales Data'!Y3:Y163,'Sales Data'!$K$3:$K$163)
A31: 2026-06-12 | B31: Fri | C31: INFLOW | D31: Daily Sales Revenue | E31: REV-06-12 | F31: =SUMPRODUCT('Sales Data'!Z3:Z163,'Sales Data'!$L$3:$L$163)
A32: 2026-06-12 | B32: Fri | C32: OUTFLOW | D32: Daily COGS — Inventory Cost | E32: COGS-06-12 | F32: =SUMPRODUCT('Sales Data'!Z3:Z163,'Sales Data'!$K$3:$K$163)
A33: 2026-06-12 | B33: Fri | C33: OUTFLOW | D33: Operating Expense: Wrapping & packing tape | E33: EXP-06-12 | F33: 1200
A34: 2026-06-13 | B34: Sat | C34: INFLOW | D34: Daily Sales Revenue | E34: REV-06-13 | F34: =SUMPRODUCT('Sales Data'!AA3:AA163,'Sales Data'!$L$3:$L$163)
A35: 2026-06-13 | B35: Sat | C35: OUTFLOW | D35: Daily COGS — Inventory Cost | E35: COGS-06-13 | F35: =SUMPRODUCT('Sales Data'!AA3:AA163,'Sales Data'!$K$3:$K$163)
A36: 2026-06-14 | B36: Sun | C36: INFLOW | D36: Daily Sales Revenue | E36: REV-06-14 | F36: =SUMPRODUCT('Sales Data'!AB3:AB163,'Sales Data'!$L$3:$L$163)
A37: 2026-06-14 | B37: Sun | C37: OUTFLOW | D37: Daily COGS — Inventory Cost | E37: COGS-06-14 | F37: =SUMPRODUCT('Sales Data'!AB3:AB163,'Sales Data'!$K$3:$K$163)
A38: 2026-06-15 | B38: Mon | C38: INFLOW | D38: Daily Sales Revenue | E38: REV-06-15 | F38: =SUMPRODUCT('Sales Data'!AC3:AC163,'Sales Data'!$L$3:$L$163)
A39: 2026-06-15 | B39: Mon | C39: OUTFLOW | D39: Daily COGS — Inventory Cost | E39: COGS-06-15 | F39: =SUMPRODUCT('Sales Data'!AC3:AC163,'Sales Data'!$K$3:$K$163)
A40: 2026-06-15 | B40: Mon | C40: OUTFLOW | D40: Operating Expense: Security & safety supplies | E40: EXP-06-15 | F40: 3400
...

Sheet Expense Tracker
A1: Al-Noor Trading — Expense Tracker (June 2026)
A2: Expense Date | B2: Category | C2: Description | D2: Vendor | E2: Status | F2: Tax Amount (PKR) | G2: Amount (PKR)
A3: 2026-06-01 | B3: SUPPLIES | C3: Office stationery & supplies | D3: Bazm-e-iqbal | E3: ACTIVE | F3: 0 | G3: 2500
A4: 2026-06-02 | B4: SUPPLIES | C4: Packaging materials | D4: Falak Foods | E4: ACTIVE | F4: 0 | G4: 3200
A5: 2026-06-04 | B5: SUPPLIES | C5: Cleaning & hygiene supplies | D5: GSK Pakistan | E5: ACTIVE | F5: 0 | G5: 1800
A6: 2026-06-06 | B6: SUPPLIES | C6: Display & shelving items | D6: Gul Ahmed | E6: ACTIVE | F6: 0 | G6: 4500
A7: 2026-06-08 | B7: SUPPLIES | C7: Printer paper & ink cartridges | D7: Bazm-e-iqbal | E7: ACTIVE | F7: 0 | G7: 2750
A8: 2026-06-10 | B8: SUPPLIES | C8: Storage boxes & labels | D8: Falak Foods | E8: ACTIVE | F8: 0 | G8: 1950
A9: 2026-06-12 | B9: SUPPLIES | C9: Wrapping & packing tape | D9: Falak Foods | E9: ACTIVE | F9: 0 | G9: 1200
A10: 2026-06-15 | B10: SUPPLIES | C10: Security & safety supplies | D10: GSK Pakistan | E10: ACTIVE | F10: 0 | G10: 3400
A11: 2026-06-18 | B11: SUPPLIES | C11: Promotional signage material | D11: Gul Ahmed | E11: ACTIVE | F11: 0 | G11: 2800
A12: 2026-06-20 | B12: SUPPLIES | C12: Counter & billing supplies | D12: Bazm-e-iqbal | E12: ACTIVE | F12: 0 | G12: 3589.99
A13: 2026-06-23 | B13: SUPPLIES | C13: Inventory tags & barcodes | D13: Falak Foods | E13: ACTIVE | F13: 0 | G13: 2100
A14: 2026-06-27 | B14: SUPPLIES | C14: General office consumables | D14: Bazm-e-iqbal | E14: ACTIVE | F14: 0 | G14: 1800
A15: 2026-06-14 | B15: SUPPLIES | C15: Duplicate order — cancelled | D15: Grey | E15: VOIDED | F15: 0 | G15: 1500
A16: TOTAL ACTIVE EXPENSES (PKR) — 12 records, no tax | G16: =SUMIF(E3:E15,"ACTIVE",G3:G15)
A17: 1 VOIDED record (2026-06-14, Grey, PKR 1,500.00) excluded from active totals
A19: Vendor Summary (Active Expenses Only)
A20: Vendor | B20: Country | C20: Active Transactions | D20: Total Amount (PKR)
A21: Bazm-e-iqbal | B21: Pakistan | C21: =COUNTIFS(D3:D15,"Bazm-e-iqbal",E3:E15,"ACTIVE") | D21: =SUMIFS(G3:G15,D3:D15,"Bazm-e-iqbal",E3:E15,"ACTIVE")
A22: Falak Foods | B22: Pakistan | C22: =COUNTIFS(D3:D15,"Falak Foods",E3:E15,"ACTIVE") | D22: =SUMIFS(G3:G15,D3:D15,"Falak Foods",E3:E15,"ACTIVE")
A23: Gul Ahmed | B23: Pakistan | C23: =COUNTIFS(D3:D15,"Gul Ahmed",E3:E15,"ACTIVE") | D23: =SUMIFS(G3:G15,D3:D15,"Gul Ahmed",E3:E15,"ACTIVE")
A24: GSK Pakistan | B24: Pakistan | C24: =COUNTIFS(D3:D15,"GSK Pakistan",E3:E15,"ACTIVE") | D24: =SUMIFS(G3:G15,D3:D15,"GSK Pakistan",E3:E15,"ACTIVE")
A25: Grey | B25: Pakistan | C25: =COUNTIFS(D3:D15,"Grey",E3:E15,"ACTIVE") | D25: =SUMIFS(G3:G15,D3:D15,"Grey",E3:E15,"ACTIVE")

Sheet Revenue Analysis
A1: Al-Noor Trading — Revenue Analysis (June 2026)
A2: Product ID | B2: Product Name | C2: Category | D2: Sub-Category | E2: Total Qty Sold | F2: Total Revenue (PKR) | G2: Total COGS (PKR) | H2: Gross Profit (PKR)
A3: PK-1001 | B3: Samsung Galaxy A54 | C3: Electronics & Appliances | D3: Mobile Phones | E3: =SUMPRODUCT('Sales Data'!O3:AR3) | F3: =SUMPRODUCT('Sales Data'!O3:AR3)*'Sales Data'!L3 | G3: =SUMPRODUCT('Sales Data'!O3:AR3)*'Sales Data'!K3 | H3: =F3-G3
A4: PK-1002 | B4: Samsung Galaxy A34 | C4: Electronics & Appliances | D4: Mobile Phones | E4: =SUMPRODUCT('Sales Data'!O4:AR4) | F4: =SUMPRODUCT('Sales Data'!O4:AR4)*'Sales Data'!L4 | G4: =SUMPRODUCT('Sales Data'!O4:AR4)*'Sales Data'!K4 | H4: =F4-G4
A5: PK-1003 | B5: iPhone 14 | C5: Electronics & Appliances | D5: Mobile Phones | E5: =SUMPRODUCT('Sales Data'!O5:AR5) | F5: =SUMPRODUCT('Sales Data'!O5:AR5)*'Sales Data'!L5 | G5: =SUMPRODUCT('Sales Data'!O5:AR5)*'Sales Data'!K5 | H5: =F5-G5
A6: PK-1004 | B6: iPhone 13 | C6: Electronics & Appliances | D6: Mobile Phones | E6: =SUMPRODUCT('Sales Data'!O6:AR6) | F6: =SUMPRODUCT('Sales Data'!O6:AR6)*'Sales Data'!L6 | G6: =SUMPRODUCT('Sales Data'!O6:AR6)*'Sales Data'!K6 | H6: =F6-G6
A7: PK-1005 | B7: Vivo Y36 | C7: Electronics & Appliances | D7: Mobile Phones | E7: =SUMPRODUCT('Sales Data'!O7:AR7) | F7: =SUMPRODUCT('Sales Data'!O7:AR7)*'Sales Data'!L7 | G7: =SUMPRODUCT('Sales Data'!O7:AR7)*'Sales Data'!K7 | H7: =F7-G7
A8: PK-1006 | B8: Vivo V27 | C8: Electronics & Appliances | D8: Mobile Phones | E8: =SUMPRODUCT('Sales Data'!O8:AR8) | F8: =SUMPRODUCT('Sales Data'!O8:AR8)*'Sales Data'!L8 | G8: =SUMPRODUCT('Sales Data'!O8:AR8)*'Sales Data'!K8 | H8: =F8-G8
A9: PK-1007 | B9: Oppo A78 | C9: Electronics & Appliances | D9: Mobile Phones | E9: =SUMPRODUCT('Sales Data'!O9:AR9) | F9: =SUMPRODUCT('Sales Data'!O9:AR9)*'Sales Data'!L9 | G9: =SUMPRODUCT('Sales Data'!O9:AR9)*'Sales Data'!K9 | H9: =F9-G9
A10: PK-1008 | B10: Oppo Reno10 | C10: Electronics & Appliances | D10: Mobile Phones | E10: =SUMPRODUCT('Sales Data'!O10:AR10) | F10: =SUMPRODUCT('Sales Data'!O10:AR10)*'Sales Data'!L10 | G10: =SUMPRODUCT('Sales Data'!O10:AR10)*'Sales Data'!K10 | H10: =F10-G10
A11: PK-1009 | B11: Realme 11 Pro | C11: Electronics & Appliances | D11: Mobile Phones | E11: =SUMPRODUCT('Sales Data'!O11:AR11) | F11: =SUMPRODUCT('Sales Data'!O11:AR11)*'Sales Data'!L11 | G11: =SUMPRODUCT('Sales Data'!O11:AR11)*'Sales Data'!K11 | H11: =F11-G11
A12: PK-1010 | B12: Xiaomi Redmi 12 | C12: Electronics & Appliances | D12: Mobile Phones | E12: =SUMPRODUCT('Sales Data'!O12:AR12) | F12: =SUMPRODUCT('Sales Data'!O12:AR12)*'Sales Data'!L12 | G12: =SUMPRODUCT('Sales Data'!O12:AR12)*'Sales Data'!K12 | H12: =F12-G12
A13: PK-1011 | B13: Dell Inspiron 15 | C13: Electronics & Appliances | D13: Laptops & Computers | E13: =SUMPRODUCT('Sales Data'!O13:AR13) | F13: =SUMPRODUCT('Sales Data'!O13:AR13)*'Sales Data'!L13 | G13: =SUMPRODUCT('Sales Data'!O13:AR13)*'Sales Data'!K13 | H13: =F13-G13
A14: PK-1012 | B14: HP Pavilion 14 | C14: Electronics & Appliances | D14: Laptops & Computers | E14: =SUMPRODUCT('Sales Data'!O14:AR14) | F14: =SUMPRODUCT('Sales Data'!O14:AR14)*'Sales Data'!L14 | G14: =SUMPRODUCT('Sales Data'!O14:AR14)*'Sales Data'!K14 | H14: =F14-G14
... A112: PK-1110 | B112: Men Necktie | C112: Clothing & Textiles | D112: Fabric & Accessories | E112: =SUMPRODUCT('Sales Data'!O112:AR112) | F112: =SUMPRODUCT('Sales Data'!O112:AR112)*'Sales Data'!L112 | G112: =SUMPRODUCT('Sales Data'!O112:AR112)*'Sales Data'!K112 | H112: =F112-G112
A113: PK-1144 | B113: Panadol Extra 20tabs | C113: Pharmaceuticals & Health | D113: OTC Medicines | E113: =SUMPRODUCT('Sales Data'!O113:AR113) | F113: =SUMPRODUCT('Sales Data'!O113:AR113)*'Sales Data'!L113 | G113: =SUMPRODUCT('Sales Data'!O113:AR113)*'Sales Data'!K113 | H113: =F146-G146
A114: PK-1145 | B114: Panadol CF 10tabs | C114: Pharmaceuticals & Health | D114: OTC Medicines | E114: =SUMPRODUCT('Sales Data'!O114:AR114) | F114: =SUMPRODUCT('Sales Data'!O114:AR114)*'Sales Data'!L114 | G114: =SUMPRODUCT('Sales Data'!O114:AR114)*'Sales Data'!K114 | H114: =F147-G147
A115: PK-1146 | B115: Brufen 400mg 10tabs | C115: Pharmaceuticals & Health | D115: OTC Medicines | E115: =SUMPRODUCT('Sales Data'!O115:AR115) | F115: =SUMPRODUCT('Sales Data'!O115:AR115)*'Sales Data'!L115 | G115: =SUMPRODUCT('Sales Data'!O115:AR115)*'Sales Data'!K115 | H115: =F148-G148
A116: PK-1147 | B116: Disprin 10tabs | C116: Pharmaceuticals & Health | D116: OTC Medicines | E116: =SUMPRODUCT('Sales Data'!O116:AR116) | F116: =SUMPRODUCT('Sales Data'!O116:AR116)*'Sales Data'!L116 | G116: =SUMPRODUCT('Sales Data'!O116:AR116)*'Sales Data'!K116 | H116: =F149-G149
A117: PK-1148 | B117: ORS Sachets x10 | C117: Pharmaceuticals & Health | D117: OTC Medicines | E117: =SUMPRODUCT('Sales Data'!O117:AR117) | F117: =SUMPRODUCT('Sales Data'!O117:AR117)*'Sales Data'!L117 | G117: =SUMPRODUCT('Sales Data'!O117:AR117)*'Sales Data'!K117 | H117: =F150-G150
A118: PK-1149 | B118: Vitamin C 500mg x30 | C118: Pharmaceuticals & Health | D118: OTC Medicines | E118: =SUMPRODUCT('Sales Data'!O118:AR118) | F118: =SUMPRODUCT('Sales Data'!O118:AR118)*'Sales Data'!L118 | G118: =SUMPRODUCT('Sales Data'!O118:AR118)*'Sales Data'!K118 | H118: =F151-G151
A119: PK-1150 | B119: Omeprazole 20mg x14 | C119: Pharmaceuticals & Health | D119: OTC Medicines | E119: =SUMPRODUCT('Sales Data'!O119:AR119) | F119: =SUMPRODUCT('Sales Data'!O119:AR119)*'Sales Data'!L119 | G119: =SUMPRODUCT('Sales Data'!O119:AR119)*'Sales Data'!K119 | H119: =F152-G152
A120: PK-1151 | B120: Antacid 100ml Syrup | C120: Pharmaceuticals & Health | D120: OTC Medicines | E120: =SUMPRODUCT('Sales Data'!O120:AR120) | F120: =SUMPRODUCT('Sales Data'!O120:AR120)*'Sales Data'!L120 | G120: =SUMPRODUCT('Sales Data'!O120:AR120)*'Sales Data'!K120 | H120: =F153-G153
A121: PK-1152 | B121: Cough Syrup 100ml | C121: Pharmaceuticals & Health | D121: OTC Medicines | E121: =SUMPRODUCT('Sales Data'!O121:AR121) | F121: =SUMPRODUCT('Sales Data'!O121:AR121)*'Sales Data'!L121 | G121: =SUMPRODUCT('Sales Data'!O121:AR121)*'Sales Data'!K121 | H121: =F154-G154
A122: PK-1153 | B122: Eye Drops 10ml | C122: Pharmaceuticals & Health | D122: OTC Medicines | E122: =SUMPRODUCT('Sales Data'!O122:AR122) | F122: =SUMPRODUCT('Sales Data'!O122:AR122)*'Sales Data'!L122 | G122: =SUMPRODUCT('Sales Data'!O122:AR122)*'Sales Data'!K122 | H122: =F155-G155
A123: PK-1154 | B123: Surgical Mask Box 50pcs | C123: Pharmaceuticals & Health | D123: Surgical & Medical Supplies | E123: =SUMPRODUCT('Sales Data'!O123:AR123) | F123: =SUMPRODUCT('Sales Data'!O123:AR123)*'Sales Data'!L123 | G123: =SUMPRODUCT('Sales Data'!O123:AR123)*'Sales Data'!K123 | H123: =F156-G156
A124: PK-1155 | B124: Latex Gloves M Box 100 | C124: Pharmaceuticals & Health | D124: Surgical & Medical Supplies | E124: =SUMPRODUCT('Sales Data'!O124:AR124) | F124: =SUMPRODUCT('Sales Data'!O124:AR124)*'Sales Data'!L124 | G124: =SUMPRODUCT('Sales Data'!O124:AR124)*'Sales Data'!K124 | H124: =F157-G157
... A163: PK-1194 | B163: Calculator Scientific | C163: Stationery & Office Supplies | D163: Office Equipment | E163: =SUMPRODUCT('Sales Data'!O163:AR163) | F163: =SUMPRODUCT('Sales Data'!O163:AR163)*'Sales Data'!L163 | G163: =SUMPRODUCT('Sales Data'!O163:AR163)*'Sales Data'!K163 | H163: =F196-G196
A164: TOTALS | E164: =SUM(E3:E163) | F164: =SUM(F3:F163) | G164: =SUM(G3:G163) | H164: =SUM(H3:H163)

Sheet Category Summary
A1: Sales Summary by Category & Sub-Category
A2: Category | B2: Sub-Category | C2: # Products | D2: Total Units Sold | E2: Avg Units/Product | F2: Min Units | G2: Max Units | H2: Avg Daily Sales
A3: Electronics & Appliances | B3: Mobile Phones | C3: 10 | D3: 162 | E3: 16.2 | F3: 11 | G3: 24 | H3: 5.4
A4: Electronics & Appliances | B4: Laptops & Computers | C4: 8 | D4: 98 | E4: 12.2 | F4: 0 | G4: 19 | H4: 3.3
A5: Electronics & Appliances | B5: Televisions | C5: 8 | D5: 144 | E5: 18 | F5: 10 | G5: 27 | H5: 4.8
A6: Electronics & Appliances | B6: Home Appliances | C6: 10 | D6: 153 | E6: 15.3 | F6: 8 | G6: 21 | H6: 5.1
A7: Grocery & Food Items | B7: Staple Foods | C7: 10 | D7: 4740 | E7: 474 | F7: 359 | G7: 553 | H7: 158
A8: Grocery & Food Items | B8: Spices & Condiments | C8: 10 | D8: 3054 | E8: 305.4 | F8: 284 | G8: 362 | H8: 101.8
A9: Grocery & Food Items | B9: Beverages | C9: 10 | D9: 4011 | E9: 401.1 | F9: 346 | G9: 443 | H9: 133.7
A10: Grocery & Food Items | B10: Dairy & Frozen | C10: 8 | D10: 2972 | E10: 371.5 | F10: 340 | G10: 416 | H10: 99.1
A11: Clothing & Textiles | B11: Men's Wear | C11: 10 | D11: 1266 | E11: 126.6 | F11: 106 | G11: 148 | H11: 42.2
A12: Clothing & Textiles | B12: Women's Wear | C12: 10 | D12: 1611 | E12: 161.1 | F12: 140 | G12: 184 | H12: 53.7
A13: Clothing & Textiles | B13: Footwear | C13: 8 | D13: 988 | E13: 123.5 | F13: 109 | G13: 135 | H13: 32.9
A14: Clothing & Textiles | B14: Fabric & Accessories | C14: 8 | D14: 1256 | E14: 157 | F14: 140 | G14: 176 | H14: 41.9
... A20: Stationery & Office Supplies | B20: Office Equipment | C20: 9 | D20: 1696 | E20: 188.4 | F20: 167 | G20: 213 | H20: 56.5
A21: GRAND TOTAL | D21: 33647

Sheet Daily Totals
A1: Daily Sales Totals by Category
A2: Date | B2: Electronics & Appliances | C2: Grocery & Food Items | D2: Clothing & Textiles | E2: Pharmaceuticals & Health | F2: Stationery & Office Supplies | G2: Day Total
A3: 46174 | B3: 21 | C3: 454 | D3: 149 | E3: 235 | F3: 153 | G3: 1012
A4: 46175 | B4: 24 | C4: 470 | D4: 136 | E4: 267 | F4: 137 | G4: 1034
A5: 46176 | B5: 17 | C5: 526 | D5: 159 | E5: 273 | F5: 155 | G5: 1130
A6: 46177 | B6: 28 | C6: 454 | D6: 151 | E6: 280 | F6: 151 | G6: 1064
A7: 46178 | B7: 16 | C7: 479 | D7: 205 | E7: 300 | F7: 203 | G7: 1203
A8: 46179 | B8: 20 | C8: 560 | D8: 234 | E8: 292 | F8: 198 | G8: 1304
A9: 46180 | B9: 27 | C9: 450 | D9: 161 | E9: 232 | F9: 150 | G9: 1020
A10: 46181 | B10: 19 | C10: 518 | D10: 160 | E10: 228 | F10: 156 | G10: 1081
A11: 46182 | B11: 22 | C11: 529 | D11: 167 | E11: 260 | F11: 170 | G11: 1148
A12: 46183 | B12: 24 | C12: 445 | D12: 161 | E12: 312 | F12: 162 | G12: 1104
A13: 46184 | B13: 10 | C13: 467 | D13: 138 | E13: 260 | F13: 179 | G13: 1054
A14: 46185 | B14: 14 | C14: 512 | D14: 192 | E14: 294 | F14: 154 | G14: 1166
... A32: 46203 | B32: 19 | C32: 454 | D32: 161 | E32: 286 | F32: 158 | G32: 1078
A33: TOTAL | B33: 557 | C33: 14777 | D33: 5121 | E33: 8175 | F33: 5017 | G33: 33647

Sheet Sales Data
A1: Al-Noor Trading — 30-Day Sales Data (June 1 – June 30) | K1: Al-Noor Trading — 30-Day Sales Data (June 1 – June 30) | M1: Al-Noor Trading — 30-Day Sales Data (June 1 – June 30)
A2: Product ID | B2: Product Name | C2: Category | D2: Sub-Category | E2: SKU | F2: Unit | G2: Qty in Hand | H2: Reorder Level | I2: Reorder Qty | J2: Stock Value (PKR) | K2: Cost Price | L2: Sale Price (PKR) | M2: Gross Marjin | N2: Stock Status | O2: 46174 | P2: 46175 | Q2: 46176 | R2: 46177 | S2: 46178 | T2: 46179 | U2: 46180 | V2: 46181 | W2: 46182 | X2: 46183 | Y2: 46184 | Z2: 46185 | AA2: 46186 | AB2: 46187 | AC2: 46188 | AD2: 46189 | AE2: 46190 | AF2: 46191 | AG2: 46192 | AH2: 46193 | AI2: 46194 | AJ2: 46195 | AK2: 46196 | AL2: 46197 | AM2: 46198 | AN2: 46199 | AO2: 46200 | AP2: 46201 | AQ2: 46202 | AR2: 46203
A3: PK-1001 | B3: Samsung Galaxy A54 | C3: Electronics & Appliances | D3: Mobile Phones | E3: SMA54 | F3: Unit | G3: 138 | H3: 1 | I3: 10 | J3: 10350000 | K3: 75000 | L3: 95,000.00 | M3: =IF(L3=0,0,(L3-K3)/L3) | N3: In Stock | O3: 0 | P3: 2 | Q3: 3 | R3: 1 | S3: 0 | T3: 0 | U3: 3 | V3: 0 | W3: 2 | X3: 1 | Y3: 0 | Z3: 0 | AA3: 0 | AB3: 2 | AC3: 0 | AD3: 1 | AE3: 1 | AF3: 0 | AG3: 3 | AH3: 0 | AI3: 0 | AJ3: 0 | AK3: 0 | AL3: 0 | AM3: 0 | AN3: 0 | AO3: 3 | AP3: 2 | AQ3: 0 | AR3: 0
A4: PK-1002 | B4: Samsung Galaxy A34 | C4: Electronics & Appliances | D4: Mobile Phones | E4: SMA34 | F4: Unit | G4: 74 | H4: 2 | I4: 10 | J4: 4070000 | K4: 55000 | L4: 68,000.00 | M4: =IF(L4=0,0,(L4-K4)/L4) | N4: In Stock | O4: 0 | P4: 3 | Q4: 0 | R4: 0 | S4: 0 | T4: 0 | U4: 0 | V4: 0 | W4: 1 | X4: 0 | Y4: 0 | Z4: 3 | AA4: 0 | AB4: 1 | AC4: 0 | AD4: 1 | AE4: 0 | AF4: 0 | AG4: 0 | AH4: 1 | AI4: 1 | AJ4: 0 | AK4: 2 | AL4: 0 | AM4: 0 | AN4: 1 | AO4: 0 | AP4: 0 | AQ4: 0 | AR4: 0
A5: PK-1003 | B5: iPhone 14 | C5: Electronics & Appliances | D5: Mobile Phones | E5: IPH14 | F5: Unit | G5: 7 | H5: 1 | I5: 5 | J5: 1680000 | K5: 240000 | L5: 279,000.00 | M5: =IF(L5=0,0,(L5-K5)/L5) | N5: In Stock | O5: 0 | P5: 3 | Q5: 0 | R5: 3 | S5: 0 | T5: 1 | U5: 0 | V5: 0 | W5: 0 | X5: 0 | Y5: 0 | Z5: 0 | AA5: 0 | AB5: 0 | AC5: 0 | AD5: 0 | AE5: 1 | AF5: 1 | AG5: 1 | AH5: 0 | AI5: 0 | AJ5: 2 | AK5: 0 | AL5: 0 | AM5: 0 | AN5: 0 | AO5: 0 | AP5: 0 | AQ5: 0 | AR5: 0
A6: PK-1004 | B6: iPhone 13 | C6: Electronics & Appliances | D6: Mobile Phones | E6: IPH13 | F6: Unit | G6: 53 | H6: 1 | I6: 5 | J6: 9805000 | K6: 185000 | L6: 215,000.00 | M6: =IF(L6=0,0,(L6-K6)/L6) | N6: In Stock | O6: 0 | P6: 0 | Q6: 0 | R6: 1 | S6: 0 | T6: 2 | U6: 0 | V6: 0 | W6: 2 | X6: 1 | Y6: 0 | Z6: 0 | AA6: 0 | AB6: 1 | AC6: 1 | AD6: 0 | AE6: 2 | AF6: 0 | AG6: 0 | AH6: 1 | AI6: 0 | AJ6: 0 | AK6: 0 | AL6: 2 | AM6: 2 | AN6: 0 | AO6: 1 | AP6: 0 | AQ6: 1 | AR6: 1
A7: PK-1005 | B7: Vivo Y36 | C7: Electronics & Appliances | D7: Mobile Phones | E7: VIVY36 | F7: Unit | G7: 65 | H7: 3 | I7: 15 | J7: 2730000 | K7: 42000 | L7: 52,000.00 | M7: =IF(L7=0,0,(L7-K7)/L7) | N7: In Stock | O7: 1 | P7: 0 | Q7: 0 | R7: 1 | S7: 0 | T7: 1 | U7: 0 | V7: 1 | W7: 0 | X7: 0 | Y7: 0 | Z7: 2 | AA7: 0 | AB7: 1 | AC7: 0 | AD7: 0 | AE7: 1 | AF7: 0 | AG7: 0 | AH7: 1 | AI7: 2 | AJ7: 0 | AK7: 0 | AL7: 0 | AM7: 1 | AN7: 0 | AO7: 1 | AP7: 2 | AQ7: 0 | AR7: 3
A8: PK-1006 | B8: Vivo V27 | C8: Electronics & Appliances | D8: Mobile Phones | E8: VIVV27 | F8: Unit | G8: 12 | H8: 2 | I8: 10 | J8: 780000 | K8: 65000 | L8: 80,000.00 | M8: =IF(L8=0,0,(L8-K8)/L8) | N8: In Stock | O8: 2 | P8: 0 | Q8: 1 | R8: 0 | S8: 1 | T8: 0 | U8: 0 | V8: 0 | W8: 0 | X8: 0 | Y8: 0 | Z8: 0 | AA8: 1 | AB8: 0 | AC8: 1 | AD8: 0 | AE8: 0 | AF8: 0 | AG8: 0 | AH8: 0 | AI8: 0 | AJ8: 0 | AK8: 0 | AL8: 1 | AM8: 0 | AN8: 0 | AO8: 0 | AP8: 0 | AQ8: 2 | AR8: 2
A9: PK-1007 | B9: Oppo A78 | C9: Electronics & Appliances | D9: Mobile Phones | E9: OPPA78 | F9: Unit | G9: 101 | H9: 3 | I9: 15 | J9: 3838000 | K9: 38000 | L9: 47,000.00 | M9: =IF(L9=0,0,(L9-K9)/L9) | N9: In Stock | O9: 3 | P9: 1 | Q9: 0 | R9: 0 | S9: 0 | T9: 0 | U9: 0 | V9: 2 | W9: 0 | X9: 3 | Y9: 1 | Z9: 0 | AA9: 0 | AB9: 1 | AC9: 0 | AD9: 0 | AE9: 1 | AF9: 2 | AG9: 0 | AH9: 0 | AI9: 0 | AJ9: 0 | AK9: 0 | AL9: 1 | AM9: 0 | AN9: 0 | AO9: 0 | AP9: 1 | AQ9: 0 | AR9: 0
A10: PK-1008 | B10: Oppo Reno10 | C10: Electronics & Appliances | D10: Mobile Phones | E10: OPPR10 | F10: Unit | G10: 96 | H10: 1 | I10: 8 | J10: 7872000 | K10: 82000 | L10: 99,000.00 | M10: =IF(L10=0,0,(L10-K10)/L10) | N10: In Stock | O10: 0 | P10: 0 | Q10: 1 | R10: 0 | S10: 0 | T10: 1 | U10: 0 | V10: 0 | W10: 1 | X10: 1 | Y10: 1 | Z10: 0 | AA10: 0 | AB10: 2 | AC10: 0 | AD10: 0 | AE10: 0 | AF10: 0 | AG10: 2 | AH10: 0 | AI10: 0 | AJ10: 2 | AK10: 0 | AL10: 1 | AM10: 0 | AN10: 0 | AO10: 0 | AP10: 1 | AQ10: 0 | AR10: 0
A11: PK-1009 | B11: Realme 11 Pro | C11: Electronics & Appliances | D11: Mobile Phones | E11: RLM11P | F11: Unit | G11: 34 | H11: 3 | I11: 15 | J11: 1768000 | K11: 52000 | L11: 65,000.00 | M11: =IF(L11=0,0,(L11-K11)/L11) | N11: In Stock | O11: 0 | P11: 0 | Q11: 1 | R11: 0 | S11: 0 | T11: 0 | U11: 0 | V11: 2 | W11: 0 | X11: 0 | Y11: 0 | Z11: 0 | AA11: 0 | AB11: 0 | AC11: 0 | AD11: 1 | AE11: 0 | AF11: 1 | AG11: 0 | AH11: 0 | AI11: 0 | AJ11: 3 | AK11: 2 | AL11: 1 | AM11: 0 | AN11: 1 | AO11: 1 | AP11: 0 | AQ11: 0 | AR11: 2
A12: PK-1010 | B12: Xiaomi Redmi 12 | C12: Electronics & Appliances | D12: Mobile Phones | E12: XMR12 | F12: Unit | G12: 20 | H12: 4 | I12: 20 | J12: 680000 | K12: 34000 | L12: 42,000.00 | M12: =IF(L12=0,0,(L12-K12)/L12) | N12: In Stock | O12: 0 | P12: 0 | Q12: 1 | R12: 0 | S12: 1 | T12: 0 | U12: 3 | V12: 0 | W12: 1 | X12: 0 | Y12: 0 | Z12: 1 | AA12: 1 | AB12: 2 | AC12: 3 | AD12: 0 | AE12: 0 | AF12: 1 | AG12: 0 | AH12: 0 | AI12: 0 | AJ12: 0 | AK12: 0 | AL12: 3 | AM12: 0 | AN12: 2 | AO12: 1 | AP12: 0 | AQ12: 1 | AR12: 0
A13: PK-1011 | B13: Dell Inspiron 15 | C13: Electronics & Appliances | D13: Laptops & Computers | E13: DELI15 | F13: Unit | G13: 118 | H13: 1 | I13: 5 | J13: 13570000 | K13: 115000 | L13: 139,000.00 | M13: =IF(L13=0,0,(L13-K13)/L13) | N13: In Stock | O13: 0 | P13: 1 | Q13: 0 | R13: 0 | S13: 0 | T13: 0 | U13: 0 | V13: 2 | W13: 0 | X13: 0 | Y13: 0 | Z13: 0 | AA13: 0 | AB13: 3 | AC13: 3 | AD13: 1 | AE13: 2 | AF13: 0 | AG13: 0 | AH13: 0 | AI13: 0 | AJ13: 0 | AK13: 1 | AL13: 0 | AM13: 2 | AN13: 0 | AO13: 0 | AP13: 1 | AQ13: 0 | AR13: 1
A14: PK-1012 | B14: HP Pavilion 14 | C14: Electronics & Appliances | D14: Laptops & Computers | E14: HPP14 | F14: Unit | G14: 1 | H14: 1 | I14: 5 | J14: 108000 | K14: 108000 | L14: 130,000.00 | M14: =IF(L14=0,0,(L14-K14)/L14) | N14: In Stock | O14: 0 | P14: 0 | Q14: 0 | R14: 0 | S14: 0 | T14: 0 | U14: 0 | V14: 0 | W14: 0 | X14: 0 | Y14: 0 | Z14: 0 | AA14: 0 | AB14: 0 | AC14: 0 | AD14: 0 | AE14: 0 | AF14: 0 | AG14: 0 | AH14: 0 | AI14: 0 | AJ14: 0 | AK14: 0 | AL14: 0 | AM14: 0 | AN14: 0 | AO14: 0 | AP14: 0 | AQ14: 0 | AR14: 0
... A163: PK-1194 | B163: Calculator Scientific | C163: Stationery & Office Supplies | D163: Office Equipment | E163: CALCSC | F163: Unit | G163: 102 | H163: 5 | I163: 20 | J163: 183600 | K163: 0 | L163: 2,700.00 | M163: =IF(L163=0,0,(L163-K163)/L163) | N163: In Stock | O163: 2 | P163: 4 | Q163: 6 | R163: 10 | S163: 4 | T163: 6 | U163: 1 | V163: 8 | W163: 5 | X163: 7 | Y163: 8 | Z163: 5 | AA163: 8 | AB163: 5 | AC163: 6 | AD163: 5 | AE163: 2 | AF163: 5 | AG163: 8 | AH163: 4 | AI163: 2 | AJ163: 5 | AK163: 3 | AL163: 7 | AM163: 6 | AN163: 13 | AO163: 8 | AP163: 6 | AQ163: 4 | AR163: 4

Sheet Financial Summary
A1: Al-Noor Trading — Monthly Financial Summary (June 2026)
A2: Reporting Period: 01 June 2026 – 30 June 2026 | Currency: PKR | Products: 161 Active SKUs
A4: PROFIT & LOSS
A5: Metric | B5: Amount (PKR) | C5: Notes
A6: Total Revenue (PKR) | B6: ='Revenue Analysis'!F164 | C6: Sum of (Qty × Sale Price) for all 161 products over 30 days
A7: Total COGS (PKR) | B7: ='Revenue Analysis'!G164 | C7: Sum of (Qty × Cost Price) for all 161 products over 30 days
A8: Gross Profit (PKR) | B8: =B6-B7 | C8: Total Revenue − Total COGS
A9: Gross Profit Margin (%) | B9: =IF(B6=0,0,B8/B6) | C9: Gross Profit ÷ Revenue × 100
A10: Total Operating Expenses (PKR) | B10: ='Expense Tracker'!G16 | C10: SUPPLIES category only; 12 active records; 1 voided excluded; tax = PKR 0.00
A11: Net Profit (PKR) | B11: =B8-B10 | C11: Gross Profit − Total Operating Expenses
A12: Net Profit Margin (%) | B12: =IF(B6=0,0,B11/B6) | C12: Net Profit ÷ Revenue × 100
A14: CASH FLOW
A15: Cash Flow Item | B15: Amount (PKR) | C15: Notes
A16: Total Cash Inflows (PKR) | B16: =SUMIF('Cash Flow Statement'!C:C,"INFLOW",'Cash Flow Statement'!F:F) | C16: Sales receipts from all 30 days
A17: Total Cash Outflows (PKR) | B17: =SUMIF('Cash Flow Statement'!C:C,"OUTFLOW",'Cash Flow Statement'!F:F) | C17: COGS payments + Operating expenses
A18: Net Cash Flow (PKR) | B18: =B16-B17 | C18: Total Cash Inflows minus Total Cash Outflows
A20: INVENTORY POSITION
A21: Inventory Metric | B21: Value | C21: Notes
A22: Closing Stock Value (PKR) | B22: =SUMPRODUCT('Sales Data'!G3:G163,'Sales Data'!K3:K163) | C22: Current Qty in Hand × Cost Price — all products
A23: Total Active SKUs | B23: =COUNTA('Sales Data'!A3:A163) | C23: 161 SKUs across 5 major categories
A24: Low / Out-of-Stock Products | B24: =COUNTIF('Sales Data'!N3:N163,"Low Stock") | C24: Products where Qty in Hand ≤ Reorder Level
A25: Average Daily Sales Volume | B25: ='Revenue Analysis'!E164/30 | C25: Total units sold over 30 days ÷ 30
